Traceback (most recent call last):
  File "C:\Users\otodo\anaconda3\envs\geosmart\lib\site-packages\jupyter_cache\executors\utils.py", line 51, in single_nb_execution
    executenb(
  File "C:\Users\otodo\anaconda3\envs\geosmart\lib\site-packages\nbclient\client.py", line 1204, in execute
    return NotebookClient(nb=nb, resources=resources, km=km, **kwargs).execute()
  File "C:\Users\otodo\anaconda3\envs\geosmart\lib\site-packages\nbclient\util.py", line 84, in wrapped
    return just_run(coro(*args, **kwargs))
  File "C:\Users\otodo\anaconda3\envs\geosmart\lib\site-packages\nbclient\util.py", line 62, in just_run
    return loop.run_until_complete(coro)
  File "C:\Users\otodo\anaconda3\envs\geosmart\lib\asyncio\base_events.py", line 646, in run_until_complete
    return future.result()
  File "C:\Users\otodo\anaconda3\envs\geosmart\lib\site-packages\nbclient\client.py", line 663, in async_execute
    await self.async_execute_cell(
  File "C:\Users\otodo\anaconda3\envs\geosmart\lib\site-packages\nbclient\client.py", line 965, in async_execute_cell
    await self._check_raise_for_error(cell, cell_index, exec_reply)
  File "C:\Users\otodo\anaconda3\envs\geosmart\lib\site-packages\nbclient\client.py", line 862, in _check_raise_for_error
    raise CellExecutionError.from_cell_and_msg(cell, exec_reply_content)
nbclient.exceptions.CellExecutionError: An error occurred while executing the following cell:
------------------
# Import useful modules
import requests, zipfile, io, gzip, glob, os
import matplotlib.pyplot as plt
import numpy as np
import pandas as pd
from matplotlib import cm
%matplotlib inline
------------------

[1;31m---------------------------------------------------------------------------[0m
[1;31mModuleNotFoundError[0m                       Traceback (most recent call last)
Input [1;32mIn [1][0m, in [0;36m<cell line: 3>[1;34m()[0m
[0;32m      1[0m [38;5;66;03m# Import useful modules[39;00m
[0;32m      2[0m [38;5;28;01mimport[39;00m [38;5;21;01mrequests[39;00m[38;5;241m,[39m [38;5;21;01mzipfile[39;00m[38;5;241m,[39m [38;5;21;01mio[39;00m[38;5;241m,[39m [38;5;21;01mgzip[39;00m[38;5;241m,[39m [38;5;21;01mglob[39;00m[38;5;241m,[39m [38;5;21;01mos[39;00m
[1;32m----> 3[0m [38;5;28;01mimport[39;00m [38;5;21;01mmatplotlib[39;00m[38;5;21;01m.[39;00m[38;5;21;01mpyplot[39;00m [38;5;28;01mas[39;00m [38;5;21;01mplt[39;00m
[0;32m      4[0m [38;5;28;01mimport[39;00m [38;5;21;01mnumpy[39;00m [38;5;28;01mas[39;00m [38;5;21;01mnp[39;00m
[0;32m      5[0m [38;5;28;01mimport[39;00m [38;5;21;01mpandas[39;00m [38;5;28;01mas[39;00m [38;5;21;01mpd[39;00m

File [1;32m~\AppData\Roaming\Python\Python310\site-packages\matplotlib\__init__.py:104[0m, in [0;36m<module>[1;34m[0m
[0;32m    101[0m [38;5;28;01mimport[39;00m [38;5;21;01mtempfile[39;00m
[0;32m    102[0m [38;5;28;01mimport[39;00m [38;5;21;01mwarnings[39;00m
[1;32m--> 104[0m [38;5;28;01mimport[39;00m [38;5;21;01mnumpy[39;00m
[0;32m    105[0m [38;5;28;01mfrom[39;00m [38;5;21;01mpackaging[39;00m[38;5;21;01m.[39;00m[38;5;21;01mversion[39;00m [38;5;28;01mimport[39;00m parse [38;5;28;01mas[39;00m parse_version
[0;32m    107[0m [38;5;66;03m# cbook must import matplotlib only within function[39;00m
[0;32m    108[0m [38;5;66;03m# definitions, so it is safe to import from it here.[39;00m

[1;31mModuleNotFoundError[0m: No module named 'numpy'
ModuleNotFoundError: No module named 'numpy'

